<?xml version="1.0" ?>
<!-- =================================================================================== -->
<!-- |    This document was autogenerated by xacro from models/arm_1dof/arm_1dof_model.xacro | -->
<!-- |    EDITING THIS FILE BY HAND IS NOT RECOMMENDED                                 | -->
<!-- =================================================================================== -->
<robot name="arm_1dof">
  <material name="Black">
    <color rgba="0.0 0.0 0.0 1.0"/>
  </material>
  <material name="Red">
    <color rgba="0.8 0.0 0.0 1.0"/>
  </material>
  <material name="White">
    <color rgba="1.0 1.0 1.0 1.0"/>
  </material>
  <link name="bottom_link">
    <visual>
      <origin rpy="0 0 0" xyz="0 0 0"/>
      <geometry>
        <box size="0.1 0.1 0.5"/>
      </geometry>
    </visual>
    <collision>
      <origin rpy="0 0 0" xyz="0 0 0"/>
      <geometry>
        <box size="0.1 0.1 0.5"/>
      </geometry>
    </collision>
    <inertial>
      <mass value="100"/>
      <inertia ixx="0.03" ixy="0.0" ixz="0.0" iyy="0.03" iyz="0.0" izz="0.03"/>
    </inertial>
  </link>
  <gazebo reference="bottom_link">
    <material>Gazebo/Red</material>
  </gazebo>
  <link name="top_link">
    <visual>
      <origin rpy="0 0 0" xyz="0.05 0 0.2"/>
      <geometry>
        <box size="0.1 0.1 0.4"/>
      </geometry>
    </visual>
    <collision>
      <origin rpy="0 0 0" xyz="0.05 0 0.2"/>
      <geometry>
        <box size="0.1 0.1 0.4"/>
      </geometry>
    </collision>
    <inertial>
      <mass value="0.1"/>
      <inertia ixx="0.03" ixy="0.0" ixz="0.0" iyy="0.03" iyz="0.0" izz="0.03"/>
    </inertial>
  </link>
  <gazebo reference="top_link">
    <material>Gazebo/White</material>
  </gazebo>
  <joint name="joint1" type="revolute">
    <origin rpy="0 0 0" xyz="0.05 0 0.2"/>
    <parent link="bottom_link"/>
    <child link="top_link"/>
    <axis xyz="1 0 0"/>
    <limit effort="100.0" lower="-1.57" upper="1.57" velocity="1.0"/>
  </joint>
  <ros2_control name="GazeboSystem" type="system">
    <hardware>
      <plugin>gazebo_ros2_control/GazeboSystem</plugin>
    </hardware>
    <joint name="joint1">
      <command_interface name="position">
        <param name="min">-6.2832</param>
        <param name="max">6.2832</param>
      </command_interface>
      <state_interface name="position"/>
      <state_interface name="velocity"/>
      <state_interface name="effort"/>
    </joint>
  </ros2_control>
  <gazebo>
    <plugin filename="libgazebo_ros2_control.so" name="gazebo_ros2_control">
      <robot_sim_type>gazebo_ros2_control/GazeboSystem</robot_sim_type>
      <parameters>/home/leo/arm_ws/install/simple_robot_description/share/simple_robot_description/config/arm_1dof.yaml</parameters>
    </plugin>
  </gazebo>
</robot>
